<?xml version="1.0" encoding="utf-8"?>
<!-- This URDF was automatically created by SolidWorks to URDF Exporter! Originally created by Stephen Brawner (brawner@gmail.com) 
     Commit Version: 1.6.0-4-g7f85cfe  Build Version: 1.6.7995.38578
     For more information, please see http://wiki.ros.org/sw_urdf_exporter -->
<robot
  name="arm.SLDASM">
  <link
    name="Base_Link">
    <!-- <inertial>
      <origin
        xyz="-0.00047833 9.3248E-09 0.017484"
        rpy="0 0 0" />
      <mass
        value="1.0401" />
      <inertia
        ixx="0.0034399"
        ixy="2.4854E-19"
        ixz="6.904E-09"
        iyy="0.0034411"
        iyz="-2.1685E-19"
        izz="0.0064134" />
    </inertial> --> 
    <visual>
      <origin
        xyz="0 0 0"
        rpy="0 0 0" />
      <geometry>
        <mesh
          filename="arm_description/meshes/base_link_convex.STL" />
      </geometry>
      <material
        name="">
        <color
          rgba="0.75294 0.75294 0.75294 1" />
      </material>
    </visual>
    <collision>
      <origin
        xyz="0 0 0"
        rpy="0 0 0" />
      <geometry>
        <mesh
          filename="arm_description/meshes/base_link_convex.STL" />
      </geometry>
    </collision>
  </link>
  <link
    name="Link_0">
    <!--<inertial>
      <origin
        xyz="-7.8597E-08 -0.00028755 0.011814"
        rpy="0 0 0" />
      <mass
        value="0.1234" />
      <inertia
        ixx="9.6329E-05"
        ixy="-1.9852E-19"
        ixz="-3.9588E-19"
        iyy="9.4959E-05"
        iyz="1.3325E-09"
        izz="0.00017146" />
    </inertial>-->
    <visual>
      <origin
        xyz="0 0 0.0415"
        rpy="0 0 0" />
      <geometry>
        <mesh
          filename="arm_description/meshes/link_0_convex.STL" />
      </geometry>
      <material
        name="">
        <color
          rgba="0.75294 0.75294 0.75294 1" />
      </material>
    </visual>
    <collision>
      <origin
        xyz="0 0 0.0415"
        rpy="0 0 0" />
      <geometry>
        <mesh
          filename="arm_description/meshes/link_0_convex.STL" />
      </geometry>
    </collision>
  </link>
  <joint
    name="Joint_0"
    type="revolute">
    <origin
      xyz="0 0 0.0585"
      rpy="0 0 0" />
    <parent
      link="Base_Link" />
    <child
      link="Link_0" />
    <axis
      xyz="0 0 -1" />
    <limit
      lower="-6.28"
      upper="6.28"
      effort="0"
      velocity="0" />
  </joint>
  <link
    name="Link_1">
    <!--<inertial>
      <origin
        xyz="-7.8597E-08 -0.00028755 0.011814"
        rpy="0 0 0" />
      <mass
        value="0.1234" />
      <inertia
        ixx="9.6329E-05"
        ixy="-1.9852E-19"
        ixz="-3.9588E-19"
        iyy="9.4959E-05"
        iyz="1.3325E-09"
        izz="0.00017146" />
    </inertial>-->
    <visual>
      <origin
        xyz="0.02075 0 0.1175"
        rpy="0 0 0" />
      <geometry>
        <mesh
          filename="arm_description/meshes/link_1_convex.STL" />
      </geometry>
      <material
        name="">
        <color
          rgba="0.75294 0.75294 0.75294 1" />
      </material>
    </visual>
    <collision>
      <origin
        xyz="0.02075 0 0.1175"
        rpy="0 0 0" />
      <geometry>
        <mesh
          filename="arm_description/meshes/link_1_convex.STL" />
      </geometry>
    </collision>
  </link>
  <joint
    name="Joint_1"
    type="revolute">
    <origin
      xyz="0 0 0.0415"
      rpy="0 0 0" />
    <parent
      link="Link_0" />
    <child
      link="Link_1" />
    <axis
      xyz="0 -1 0" />
    <limit
      lower="-1.63"
      upper="1.63"
      effort="0"
      velocity="0" />
  </joint>
  <link
    name="Link_2">
    <!--<inertial>
      <origin
        xyz="-7.8597E-08 -0.00028755 0.011814"
        rpy="0 0 0" />
      <mass
        value="0.1234" />
      <inertia
        ixx="9.6329E-05"
        ixy="-1.9852E-19"
        ixz="-3.9588E-19"
        iyy="9.4959E-05"
        iyz="1.3325E-09"
        izz="0.00017146" />
    </inertial>-->
    <visual>
      <origin
        xyz="0.1375 0 0"
        rpy="0 0 0" />
      <geometry>
        <mesh
          filename="arm_description/meshes/link_2_convex.STL" />
      </geometry>
      <material
        name="">
        <color
          rgba="0.75294 0.75294 0.75294 1" />
      </material>
    </visual>
    <collision>
      <origin
        xyz="0.1375 0 0"
        rpy="0 0 0" />
      <geometry>
        <mesh
          filename="arm_description/meshes/link_2_convex.STL" />
      </geometry>
    </collision>
  </link>
  <joint
    name="Joint_2"
    type="revolute">
    <origin
      xyz="0.02075 0 0.1175"
      rpy="0 0 0" />
    <parent
      link="Link_1" />
    <child
      link="Link_2" />
    <axis
      xyz="0 -1 0" />
    <limit
      lower="-0.75"
      upper="1.77"
      effort="0"
      velocity="0" />
  </joint>
  <link
    name="Link_3">
    <!--<inertial>
      <origin
        xyz="-7.8597E-08 -0.00028755 0.011814"
        rpy="0 0 0" />
      <mass
        value="0.1234" />
      <inertia
        ixx="9.6329E-05"
        ixy="-1.9852E-19"
        ixz="-3.9588E-19"
        iyy="9.4959E-05"
        iyz="1.3325E-09"
        izz="0.00017146" />
    </inertial>-->
    <visual>
      <origin
        xyz="0.074 0 -0.0205"
        rpy="0 0 0" />
      <geometry>
        <mesh
          filename="arm_description/meshes/link_3_convex.STL" />
      </geometry>
      <material
        name="">
        <color
          rgba="0.75294 0.75294 0.75294 1" />
      </material>
    </visual>
    <collision>
      <origin
        xyz="0.074 0 -0.0205"
        rpy="0 0 0" />
      <geometry>
        <mesh
          filename="arm_description/meshes/link_3_convex.STL" />
      </geometry>
    </collision>
  </link>
  <joint
    name="Joint_3"
    type="revolute">
    <origin
      xyz="0.1375 0 0"
      rpy="0 0 0" />
    <parent
      link="Link_2" />
    <child
      link="Link_3" />
    <axis
      xyz="0 -1 0" />
    <limit
      lower="-1.77"
      upper="1.77"
      effort="0"
      velocity="0" />
  </joint>
  <link
    name="Link_gripper_r">
    <!--<inertial>
      <origin
        xyz="-7.8597E-08 -0.00028755 0.011814"
        rpy="0 0 0" />
      <mass
        value="0.1234" />
      <inertia
        ixx="9.6329E-05"
        ixy="-1.9852E-19"
        ixz="-3.9588E-19"
        iyy="9.4959E-05"
        iyz="1.3325E-09"
        izz="0.00017146" />
    </inertial>-->
    <visual>
      <origin
        xyz="0 0.006 0"
        rpy="0 0 0" />
      <geometry>
        <mesh
          filename="arm_description/meshes/gripper_convex.STL" />
      </geometry>
      <material
        name="">
        <color
          rgba="0.75294 0.75294 0.75294 1" />
      </material>
    </visual>
    <collision>
      <origin
        xyz="0 0.006 0"
        rpy="0 0 0" />
      <geometry>
        <mesh
          filename="arm_description/meshes/gripper_convex.STL" />
      </geometry>
    </collision>
  </link>
  <joint
    name="Joint_gripper_r"
    type="prismatic">
    <origin
      xyz="0.081 0 -0.02045"
      rpy="0 0 0" />
    <parent
      link="Link_3" />
    <child
      link="Link_gripper_r" />
    <axis
      xyz="0 1 0" />
    <limit
      lower="0"
      upper="0.042"
      effort="0"
      velocity="0" />
  </joint>
  <link
    name="Link_gripper_l">
    <!--<inertial>
      <origin
        xyz="-7.8597E-08 -0.00028755 0.011814"
        rpy="0 0 0" />
      <mass
        value="0.1234" />
      <inertia
        ixx="9.6329E-05"
        ixy="-1.9852E-19"
        ixz="-3.9588E-19"
        iyy="9.4959E-05"
        iyz="1.3325E-09"
        izz="0.00017146" />
    </inertial>-->
    <visual>
      <origin
        xyz="0 -0.006 0"
        rpy="3.14159265 0 0" />
      <geometry>
        <mesh
          filename="arm_description/meshes/gripper_convex.STL" />
      </geometry>
      <material
        name="">
        <color
          rgba="0.75294 0.75294 0.75294 1" />
      </material>
    </visual>
    <collision>
      <origin
        xyz="0 -0.006 0"
        rpy="3.14159265 0 0" />
      <geometry>
        <mesh
          filename="arm_description/meshes/gripper_convex.STL" />
      </geometry>
    </collision>
  </link>
  <joint
    name="Joint_gripper_l"
    type="prismatic">
    <origin
      xyz="0.081 0 -0.02045"
      rpy="0 0 0" />
    <parent
      link="Link_3" />
    <child
      link="Link_gripper_l" />
    <axis
      xyz="0 -1 0" />
    <limit
      lower="0"
      upper="0.042"
      effort="0"
      velocity="0" />
  </joint>
  <link
    name="Link_tcp">
  </link>
  <joint
    name="Joint_tcp"
    type="fixed">
    <origin
      xyz="0.14565 0 -0.02045"
      rpy="0 0 0" />
    <parent
      link="Link_3" />
    <child
      link="Link_tcp" />
  </joint>
</robot>
