<?xml version="1.0" ?>
<!-- =================================================================================== -->
<!-- |    This document was autogenerated by xacro from create3.urdf.xacro             | -->
<!-- |    EDITING THIS FILE BY HAND IS NOT RECOMMENDED                                 | -->
<!-- =================================================================================== -->
<robot name="create3">
  <!-- Create 3 base definition-->
  <link name="base_link">
    <visual>
      <origin rpy="0 0 1.5707963267948966" xyz="0 0 0.039200000000000006"/>
      <geometry>
        <mesh filename="create_description/meshes/body_visual.dae"/>
      </geometry>
    </visual>
    <collision name="create3_base_collision">
      <origin rpy="0 0 1.5707963267948966" xyz="0 0 0.04920000000000001"/>
      <geometry>
        <!--<cylinder length="0.06" radius="0.16399999999999998"/>-->
        <mesh filename="create_description/meshes/body_collision.stl"/>
      </geometry>
    </collision>
    <inertial>
      <origin xyz="0.0 0 0.0742"/>
      <mass value="2.3"/>
      <inertia ixx="0.016155199999999998" ixy="0.0" ixz="0.0" iyy="0.016155199999999998" iyz="0.0" izz="0.03093039999999999"/>
    </inertial>
  </link>
  <joint name="bumper_joint" type="fixed">
    <parent link="base_link"/>
    <child link="bumper"/>
    <origin xyz="0 0 0.039200000000000006"/>
  </joint>
  <link name="bumper">
    <visual>
      <geometry>
        <mesh filename="create_description/meshes/bumper_visual.dae"/>
      </geometry>
    </visual>
    <collision>
      <geometry>
        <mesh filename="create_description/meshes/bumper_collision.dae"/>
      </geometry>
    </collision>
    <inertial>
      <origin xyz="0.08 0 0.02"/>
      <mass value="0.1"/>
      <inertia ixx="0.0013483753405" ixy="0.0000000454352" ixz="0.0000014434849" iyy="0.0002521736852" iyz="-0.0000000006721" izz="0.0015442525386"/>
    </inertial>
  </link>
  <joint name="bump_front_center_joint" type="fixed">
    <parent link="base_link"/>
    <child link="bump_front_center"/>
    <origin rpy="0 0 0" xyz="0.175 0 0.039"/>
  </joint>
  <link name="bump_front_center"/>
  <joint name="bump_front_left_joint" type="fixed">
    <parent link="base_link"/>
    <child link="bump_front_left"/>
    <origin rpy="0 0 0.5235985" xyz="0.02345 -0.0875 0.025"/>
  </joint>
  <link name="bump_front_left"/>
  <joint name="bump_front_right_joint" type="fixed">
    <parent link="base_link"/>
    <child link="bump_front_right"/>
    <origin rpy="0 0 -0.5235985" xyz="0.02345 0.0875 0.025"/>
  </joint>
  <link name="bump_front_right"/>
  <joint name="bump_left_joint" type="fixed">
    <parent link="base_link"/>
    <child link="bump_left"/>
    <origin rpy="0 0 1.047193" xyz="0.0875 -0.15155 0.025"/>
  </joint>
  <link name="bump_left"/>
  <joint name="bump_right_joint" type="fixed">
    <parent link="base_link"/>
    <child link="bump_right"/>
    <origin rpy="0 0 -1.047193" xyz="0.0875 0.15155 0.025"/>
  </joint>
  <link name="bump_right"/>
  <joint name="wheel_drop_left_joint" type="prismatic">
    <parent link="base_link"/>
    <child link="wheel_drop_left"/>
    <origin rpy="-1.5707963267948966 0 0" xyz="0 0.1165 0.04020000000000001"/>
    <axis xyz="0 1 0"/>
    <limit effort="0" lower="0" upper="0.03" velocity="0"/>
    <!-- Damping is big enough to not make the body oscillate too much when it's lifted up -->
    <dynamics damping="50" friction="0.1"/>
  </joint>
  <link name="wheel_drop_left">
    <inertial>
      <mass value="0.05"/>
      <origin xyz="0 0 0"/>
      <inertia ixx="2.0833333333333336e-05" ixy="0.0" ixz="0.0" iyy="2.0833333333333336e-05" iyz="0.0" izz="2.0833333333333336e-05"/>
    </inertial>
  </link>
  <joint name="left_wheel_joint" type="continuous">
    <parent link="wheel_drop_left"/>
    <child link="left_wheel"/>
    <origin rpy="0 0 0" xyz="0 0 0"/>
    <axis xyz="0 0 1"/>
  </joint>
  <link name="left_wheel">
    <visual>
      <geometry>
        <cylinder length="0.015" radius="0.035750000000000004"/>
      </geometry>
      <!-- Give black color to wheels in Rviz -->
      <material name="black">
        <color rgba="0.1 0.1 0.1 1"/>
      </material>
    </visual>
    <collision>
      <geometry>
        <cylinder length="0.015" radius="0.035750000000000004"/>
      </geometry>
    </collision>
    <inertial>
      <origin xyz="0 0 0"/>
      <mass value="0.2"/>
      <inertia ixx="6.765312500000001e-05" ixy="0.0" ixz="0.0" iyy="6.765312500000001e-05" iyz="0.0" izz="0.00012780625000000003"/>
    </inertial>
  </link>
  <joint name="wheel_drop_right_joint" type="prismatic">
    <parent link="base_link"/>
    <child link="wheel_drop_right"/>
    <origin rpy="-1.5707963267948966 0 0" xyz="0 -0.1165 0.04020000000000001"/>
    <axis xyz="0 1 0"/>
    <limit effort="0" lower="0" upper="0.03" velocity="0"/>
    <!-- Damping is big enough to not make the body oscillate too much when it's lifted up -->
    <dynamics damping="50" friction="0.1"/>
  </joint>
  <link name="wheel_drop_right">
    <inertial>
      <mass value="0.05"/>
      <origin xyz="0 0 0"/>
      <inertia ixx="2.0833333333333336e-05" ixy="0.0" ixz="0.0" iyy="2.0833333333333336e-05" iyz="0.0" izz="2.0833333333333336e-05"/>
    </inertial>
  </link>
  <joint name="right_wheel_joint" type="continuous">
    <parent link="wheel_drop_right"/>
    <child link="right_wheel"/>
    <origin rpy="0 0 0" xyz="0 0 0"/>
    <axis xyz="0 0 1"/>
  </joint>
  <link name="right_wheel">
    <visual>
      <geometry>
        <cylinder length="0.015" radius="0.035750000000000004"/>
      </geometry>
      <!-- Give black color to wheels in Rviz -->
      <material name="black">
        <color rgba="0.1 0.1 0.1 1"/>
      </material>
    </visual>
    <collision>
      <geometry>
        <cylinder length="0.015" radius="0.035750000000000004"/>
      </geometry>
    </collision>
    <inertial>
      <origin xyz="0 0 0"/>
      <mass value="0.2"/>
      <inertia ixx="6.765312500000001e-05" ixy="0.0" ixz="0.0" iyy="6.765312500000001e-05" iyz="0.0" izz="0.00012780625000000003"/>
    </inertial>
  </link>
  <joint name="front_caster_joint" type="fixed">
    <parent link="base_link"/>
    <child link="front_caster_link"/>
    <origin rpy="-1.5707963267948966 0 0" xyz="0.125 0 0.012200000000000003"/>
  </joint>
  <link name="front_caster_link">
    <visual>
      <geometry>
        <sphere radius="0.01"/>
      </geometry>
      <!-- Give black color to caster in Rviz -->
      <material name="black">
        <color rgba="0.1 0.1 0.1 1"/>
      </material>
    </visual>
    <collision>
      <geometry>
        <sphere radius="0.01"/>
      </geometry>
    </collision>
    <inertial>
      <mass value="0.01"/>
      <inertia ixx="4.0000000000000003e-07" ixy="0.0" ixz="0.0" iyy="4.0000000000000003e-07" iyz="0.0" izz="4.0000000000000003e-07"/>
    </inertial>
  </link>
  <joint name="imu_joint" type="fixed">
    <origin xyz="0.050613 0.043673 0.0844"/>
    <parent link="base_link"/>
    <child link="imu_link"/>
  </joint>
  <link name="imu_link">
    <inertial>
      <mass value="0.01"/>
      <origin xyz="0 0 0"/>
      <inertia ixx="1.6666666666666668e-07" ixy="0.0" ixz="0.0" iyy="1.6666666666666668e-07" iyz="0.0" izz="1.6666666666666668e-07"/>
    </inertial>
  </link>
  <joint name="mouse_joint" type="fixed">
    <origin rpy="0 0 -0.7853981633974483" xyz="0.1015 0.087 0.009200000000000007"/>
    <parent link="base_link"/>
    <child link="mouse"/>
  </joint>
  <link name="mouse">
    <inertial>
      <mass value="0.01"/>
      <origin xyz="0 0 0"/>
      <inertia ixx="1.6666666666666668e-07" ixy="0.0" ixz="0.0" iyy="1.6666666666666668e-07" iyz="0.0" izz="1.6666666666666668e-07"/>
    </inertial>
  </link>
  <joint name="cliff_side_left_joint" type="fixed">
    <origin rpy="0 1.3962634015954636 2.921681167838508" xyz="0.06 0.145 0.01920000000000001"/>
    <parent link="base_link"/>
    <child link="cliff_side_left"/>
  </joint>
  <link name="cliff_side_left">
    <inertial>
      <mass value="0.01"/>
      <origin xyz="0 0 0"/>
      <inertia ixx="1.6666666666666668e-07" ixy="0.0" ixz="0.0" iyy="1.6666666666666668e-07" iyz="0.0" izz="1.6666666666666668e-07"/>
    </inertial>
  </link>
  <joint name="cliff_side_right_joint" type="fixed">
    <origin rpy="0 1.3962634015954636 -2.921681167838508" xyz="0.06 -0.145 0.01920000000000001"/>
    <parent link="base_link"/>
    <child link="cliff_side_right"/>
  </joint>
  <link name="cliff_side_right">
    <inertial>
      <mass value="0.01"/>
      <origin xyz="0 0 0"/>
      <inertia ixx="1.6666666666666668e-07" ixy="0.0" ixz="0.0" iyy="1.6666666666666668e-07" iyz="0.0" izz="1.6666666666666668e-07"/>
    </inertial>
  </link>
  <joint name="cliff_front_left_joint" type="fixed">
    <origin rpy="0 1.3962634015954636 1.1397000015522971" xyz="0.16 0.045 0.01920000000000001"/>
    <parent link="base_link"/>
    <child link="cliff_front_left"/>
  </joint>
  <link name="cliff_front_left">
    <inertial>
      <mass value="0.01"/>
      <origin xyz="0 0 0"/>
      <inertia ixx="1.6666666666666668e-07" ixy="0.0" ixz="0.0" iyy="1.6666666666666668e-07" iyz="0.0" izz="1.6666666666666668e-07"/>
    </inertial>
  </link>
  <joint name="cliff_front_right_joint" type="fixed">
    <origin rpy="0 1.3962634015954636 -1.1397000015522971" xyz="0.16 -0.045 0.01920000000000001"/>
    <parent link="base_link"/>
    <child link="cliff_front_right"/>
  </joint>
  <link name="cliff_front_right">
    <inertial>
      <mass value="0.01"/>
      <origin xyz="0 0 0"/>
      <inertia ixx="1.6666666666666668e-07" ixy="0.0" ixz="0.0" iyy="1.6666666666666668e-07" iyz="0.0" izz="1.6666666666666668e-07"/>
    </inertial>
  </link>
  <joint name="ir_intensity_front_center_left_joint" type="fixed">
    <origin xyz="0.1540 0 0.05720000000000001"/>
    <parent link="base_link"/>
    <child link="ir_intensity_front_center_left"/>
  </joint>
  <link name="ir_intensity_front_center_left">
    <inertial>
      <mass value="0.01"/>
      <origin xyz="0 0 0"/>
      <inertia ixx="1.6666666666666668e-07" ixy="0.0" ixz="0.0" iyy="1.6666666666666668e-07" iyz="0.0" izz="1.6666666666666668e-07"/>
    </inertial>
  </link>
  <joint name="ir_intensity_front_center_right_joint" type="fixed">
    <origin rpy="0 0 -0.436" xyz="0.1396 -0.0651 0.05720000000000001"/>
    <parent link="base_link"/>
    <child link="ir_intensity_front_center_right"/>
  </joint>
  <link name="ir_intensity_front_center_right">
    <inertial>
      <mass value="0.01"/>
      <origin xyz="0 0 0"/>
      <inertia ixx="1.6666666666666668e-07" ixy="0.0" ixz="0.0" iyy="1.6666666666666668e-07" iyz="0.0" izz="1.6666666666666668e-07"/>
    </inertial>
  </link>
  <joint name="ir_intensity_front_left_joint" type="fixed">
    <origin rpy="0 0 0.436" xyz="0.1396 0.0651 0.05720000000000001"/>
    <parent link="base_link"/>
    <child link="ir_intensity_front_left"/>
  </joint>
  <link name="ir_intensity_front_left">
    <inertial>
      <mass value="0.01"/>
      <origin xyz="0 0 0"/>
      <inertia ixx="1.6666666666666668e-07" ixy="0.0" ixz="0.0" iyy="1.6666666666666668e-07" iyz="0.0" izz="1.6666666666666668e-07"/>
    </inertial>
  </link>
  <joint name="ir_intensity_front_right_joint" type="fixed">
    <origin rpy="0 0 -0.873" xyz="0.0990 -0.1180 0.05720000000000001"/>
    <parent link="base_link"/>
    <child link="ir_intensity_front_right"/>
  </joint>
  <link name="ir_intensity_front_right">
    <inertial>
      <mass value="0.01"/>
      <origin xyz="0 0 0"/>
      <inertia ixx="1.6666666666666668e-07" ixy="0.0" ixz="0.0" iyy="1.6666666666666668e-07" iyz="0.0" izz="1.6666666666666668e-07"/>
    </inertial>
  </link>
  <joint name="ir_intensity_left_joint" type="fixed">
    <origin rpy="0 0 0.873" xyz="0.0990 0.1180 0.05720000000000001"/>
    <parent link="base_link"/>
    <child link="ir_intensity_left"/>
  </joint>
  <link name="ir_intensity_left">
    <inertial>
      <mass value="0.01"/>
      <origin xyz="0 0 0"/>
      <inertia ixx="1.6666666666666668e-07" ixy="0.0" ixz="0.0" iyy="1.6666666666666668e-07" iyz="0.0" izz="1.6666666666666668e-07"/>
    </inertial>
  </link>
  <joint name="ir_intensity_right_joint" type="fixed">
    <origin rpy="0 0 -1.309" xyz="0.0399 -0.1488 0.05720000000000001"/>
    <parent link="base_link"/>
    <child link="ir_intensity_right"/>
  </joint>
  <link name="ir_intensity_right">
    <inertial>
      <mass value="0.01"/>
      <origin xyz="0 0 0"/>
      <inertia ixx="1.6666666666666668e-07" ixy="0.0" ixz="0.0" iyy="1.6666666666666668e-07" iyz="0.0" izz="1.6666666666666668e-07"/>
    </inertial>
  </link>
  <joint name="ir_intensity_side_left_joint" type="fixed">
    <origin rpy="0 0 1.309" xyz="0.0399 0.1488 0.05720000000000001"/>
    <parent link="base_link"/>
    <child link="ir_intensity_side_left"/>
  </joint>
  <link name="ir_intensity_side_left">
    <inertial>
      <mass value="0.01"/>
      <origin xyz="0 0 0"/>
      <inertia ixx="1.6666666666666668e-07" ixy="0.0" ixz="0.0" iyy="1.6666666666666668e-07" iyz="0.0" izz="1.6666666666666668e-07"/>
    </inertial>
  </link>
  <joint name="button_1_joint" type="fixed">
    <parent link="base_link"/>
    <child link="button_1"/>
    <origin rpy="0 -1.5707963267948966 0" xyz="0.06 0.37 0.1442"/>
  </joint>
  <link name="button_1"/>
  <joint name="button_2_joint" type="fixed">
    <parent link="base_link"/>
    <child link="button_2"/>
    <origin rpy="0 -1.5707963267948966 0" xyz="0.06 -0.37 0.1442"/>
  </joint>
  <link name="button_2"/>
  <joint name="button_power_joint" type="fixed">
    <parent link="base_link"/>
    <child link="button_power"/>
    <origin rpy="0 -1.5707963267948966 0" xyz="0.06 0 0.1442"/>
  </joint>
  <link name="button_power"/>
  <joint name="ir_omni_joint" type="fixed">
    <origin xyz="0.153 0 0.09920000000000001"/>
    <parent link="base_link"/>
    <child link="ir_omni"/>
  </joint>
  <link name="ir_omni">
    <inertial>
      <mass value="0.01"/>
      <origin xyz="0 0 0"/>
      <inertia ixx="1.6666666666666668e-07" ixy="0.0" ixz="0.0" iyy="1.6666666666666668e-07" iyz="0.0" izz="1.6666666666666668e-07"/>
    </inertial>
  </link>
</robot>
