<?xml version="1.0" ?>
<!-- =================================================================================== -->
<!-- |    This document was autogenerated by xacro from create3.urdf.xacro             | -->
<!-- |    EDITING THIS FILE BY HAND IS NOT RECOMMENDED                                 | -->
<!-- =================================================================================== -->
<robot name="create3">
  <link name="world_link"/>
  <joint name="x_joint" type="prismatic">
    <parent link="world_link"/>
    <child link="x_link"/>
    <origin xyz="0 0 0"/>
    <axis xyz="1 0 0" />
    <limit
      lower="-5"
      upper="5"
      effort="0"
      velocity="0" />
  </joint>  
  <link name="x_link"/>
  <joint name="y_joint" type="prismatic">
    <parent link="x_link"/>
    <child link="y_link"/>
    <origin xyz="0 0 0"/>
    <axis xyz="0 1 0" />
    <limit
      lower="-5"
      upper="5"
      effort="0"
      velocity="0" />
  </joint>
  <link name="y_link"/>
  <joint name="theta_joint" type="revolute">
    <parent link="y_link"/>
    <child link="theta_link"/>
    <origin xyz="0 0 0"/>
    <axis xyz="0 0 1" />
    <limit
      lower="-6.28"
      upper="6.28"
      effort="0"
      velocity="0" />
  </joint>
  <link name="theta_link"/>
  <joint name="base_joint" type="fixed">
    <parent link="theta_link"/>
    <child link="base_link"/>
    <origin xyz="0 0 0"/>
  </joint>
  <!-- Create 3 base definition-->
  <link name="base_link">
    <visual>
      <origin rpy="0 0 1.5707963267948966" xyz="0 0 0.039200000000000006"/>
      <geometry>
        <mesh filename="create_description/meshes/body_visual.dae"/>
      </geometry>
    </visual>
    <collision name="create3_base_collision">
      <origin rpy="0 0 1.5707963267948966" xyz="0 0 0.04920000000000001"/>
      <geometry>
        <!--<cylinder length="0.06" radius="0.16399999999999998"/>-->
        <mesh filename="create_description/meshes/body_collision_convex.stl"/>
      </geometry>
    </collision>
    <inertial>
      <origin xyz="0.0 0 0.0742"/>
      <mass value="2.3"/>
      <inertia ixx="0.016155199999999998" ixy="0.0" ixz="0.0" iyy="0.016155199999999998" iyz="0.0" izz="0.03093039999999999"/>
    </inertial>
  </link>
  <joint name="bumper_joint" type="fixed">
    <parent link="base_link"/>
    <child link="bumper"/>
    <origin xyz="0 0 0.039200000000000006"/>
  </joint>
  <link name="bumper">
    <visual>
      <geometry>
        <mesh filename="create_description/meshes/bumper_visual.dae"/>
      </geometry>
    </visual>
    <collision>
      <geometry>
        <mesh filename="create_description/meshes/bumper_collision.dae"/>
      </geometry>
    </collision>
    <inertial>
      <origin xyz="0.08 0 0.02"/>
      <mass value="0.1"/>
      <inertia ixx="0.0013483753405" ixy="0.0000000454352" ixz="0.0000014434849" iyy="0.0002521736852" iyz="-0.0000000006721" izz="0.0015442525386"/>
    </inertial>
  </link>
  <joint name="arm_joint" type="fixed">
    <parent link="base_link"/>
    <child link="Base_Link"/>
    <origin xyz="0.05 0 0.095"/>	<!--0.095-0.01 -->
  </joint>
  <link
    name="Base_Link">
    <!-- <inertial>
      <origin
        xyz="-0.00047833 9.3248E-09 0.017484"
        rpy="0 0 0" />
      <mass
        value="1.0401" />
      <inertia
        ixx="0.0034399"
        ixy="2.4854E-19"
        ixz="6.904E-09"
        iyy="0.0034411"
        iyz="-2.1685E-19"
        izz="0.0064134" />
    </inertial> --> 
    <visual>
      <origin
        xyz="0 0 0"
        rpy="0 0 0" />
      <geometry>
        <mesh
          filename="arm_description/meshes/base_link_convex.STL" />
      </geometry>
      <material
        name="">
        <color
          rgba="0.75294 0.75294 0.75294 1" />
      </material>
    </visual>
    <collision>
      <origin
        xyz="0 0 0"
        rpy="0 0 0" />
      <geometry>
        <mesh
          filename="arm_description/meshes/base_link_convex.STL" />
      </geometry>
    </collision>
  </link>
  <link
    name="Link_0">
    <!--<inertial>
      <origin
        xyz="-7.8597E-08 -0.00028755 0.011814"
        rpy="0 0 0" />
      <mass
        value="0.1234" />
      <inertia
        ixx="9.6329E-05"
        ixy="-1.9852E-19"
        ixz="-3.9588E-19"
        iyy="9.4959E-05"
        iyz="1.3325E-09"
        izz="0.00017146" />
    </inertial>-->
    <visual>
      <origin
        xyz="0 0 0.0415"
        rpy="0 0 0" />
      <geometry>
        <mesh
          filename="arm_description/meshes/link_0_convex.STL" />
      </geometry>
      <material
        name="">
        <color
          rgba="0.75294 0.75294 0.75294 1" />
      </material>
    </visual>
    <collision>
      <origin
        xyz="0 0 0.0415"
        rpy="0 0 0" />
      <geometry>
        <mesh
          filename="arm_description/meshes/link_0_convex.STL" />
      </geometry>
    </collision>
  </link>
  <joint
    name="Joint_0"
    type="revolute">
    <origin
      xyz="0 0 0.0585"
      rpy="0 0 0" />
    <parent
      link="Base_Link" />
    <child
      link="Link_0" />
    <axis
      xyz="0 0 1" />
    <limit
      lower="-6.28"
      upper="6.28"
      effort="0"
      velocity="0" />
  </joint>
  <link
    name="Link_1">
    <!--<inertial>
      <origin
        xyz="-7.8597E-08 -0.00028755 0.011814"
        rpy="0 0 0" />
      <mass
        value="0.1234" />
      <inertia
        ixx="9.6329E-05"
        ixy="-1.9852E-19"
        ixz="-3.9588E-19"
        iyy="9.4959E-05"
        iyz="1.3325E-09"
        izz="0.00017146" />
    </inertial>-->
    <visual>
      <origin
        xyz="0.02075 0 0.1425"
        rpy="0 0 0" />
      <geometry>
        <mesh
          filename="arm_description/meshes/link_1_convex.STL" />
      </geometry>
      <material
        name="">
        <color
          rgba="0.75294 0.75294 0.75294 1" />
      </material>
    </visual>
    <collision>
      <origin
        xyz="0.02075 0 0.1175"
        rpy="0 0 0" />
      <geometry>
        <mesh
          filename="arm_description/meshes/link_1_convex.STL" />
      </geometry>
    </collision>
  </link>
  <joint
    name="Joint_1"
    type="revolute">
    <origin
      xyz="0 0 0.0415"
      rpy="0 0 0" />
    <parent
      link="Link_0" />
    <child
      link="Link_1" />
    <axis
      xyz="0 1 0" />
    <limit
      lower="-1.63"
      upper="1.63"
      effort="0"
      velocity="0" />
  </joint>
  <link
    name="Link_2">
    <!--<inertial>
      <origin
        xyz="-7.8597E-08 -0.00028755 0.011814"
        rpy="0 0 0" />
      <mass
        value="0.1234" />
      <inertia
        ixx="9.6329E-05"
        ixy="-1.9852E-19"
        ixz="-3.9588E-19"
        iyy="9.4959E-05"
        iyz="1.3325E-09"
        izz="0.00017146" />
    </inertial>-->
    <visual>
      <origin
        xyz="0.1375 0 0"
        rpy="0 0 0" />
      <geometry>
        <mesh
          filename="arm_description/meshes/link_2_convex.STL" />
      </geometry>
      <material
        name="">
        <color
          rgba="0.75294 0.75294 0.75294 1" />
      </material>
    </visual>
    <collision>
      <origin
        xyz="0.1375 0 0"
        rpy="0 0 0" />
      <geometry>
        <mesh
          filename="arm_description/meshes/link_2_convex.STL" />
      </geometry>
    </collision>
  </link>
  <joint
    name="Joint_2"
    type="revolute">
    <origin
      xyz="0.02075 0 0.1425"
      rpy="0 0 0" />
    <parent
      link="Link_1" />
    <child
      link="Link_2" />
    <axis
      xyz="0 1 0" />
    <limit
      lower="-1.77"
      upper="0.75"
      effort="0"
      velocity="0" />
  </joint>
  <link
    name="Link_3">
    <!--<inertial>
      <origin
        xyz="-7.8597E-08 -0.00028755 0.011814"
        rpy="0 0 0" />
      <mass
        value="0.1234" />
      <inertia
        ixx="9.6329E-05"
        ixy="-1.9852E-19"
        ixz="-3.9588E-19"
        iyy="9.4959E-05"
        iyz="1.3325E-09"
        izz="0.00017146" />
    </inertial>-->
    <visual>
      <origin
        xyz="0.074 0 -0.0205"
        rpy="0 0 0" />
      <geometry>
        <mesh
          filename="arm_description/meshes/link_3_convex.STL" />
      </geometry>
      <material
        name="">
        <color
          rgba="0.75294 0.75294 0.75294 1" />
      </material>
    </visual>
    <collision>
      <origin
        xyz="0.074 0 -0.0205"
        rpy="0 0 0" />
      <geometry>
        <mesh
          filename="arm_description/meshes/link_3_convex.STL" />
      </geometry>
    </collision>
  </link>
  <joint
    name="Joint_3"
    type="revolute">
    <origin
      xyz="0.1375 0 0"
      rpy="0 0 0" />
    <parent
      link="Link_2" />
    <child
      link="Link_3" />
    <axis
      xyz="0 1 0" />
    <limit
      lower="-1.77"
      upper="1.77"
      effort="0"
      velocity="0" />
  </joint>
  <link
    name="Link_gripper_r">
    <!--<inertial>
      <origin
        xyz="-7.8597E-08 -0.00028755 0.011814"
        rpy="0 0 0" />
      <mass
        value="0.1234" />
      <inertia
        ixx="9.6329E-05"
        ixy="-1.9852E-19"
        ixz="-3.9588E-19"
        iyy="9.4959E-05"
        iyz="1.3325E-09"
        izz="0.00017146" />
    </inertial>-->
    <visual>
      <origin
        xyz="0 0.006 0"
        rpy="0 0 0" />
      <geometry>
        <mesh
          filename="arm_description/meshes/gripper_convex.STL" />
      </geometry>
      <material
        name="">
        <color
          rgba="0.75294 0.75294 0.75294 1" />
      </material>
    </visual>
    <collision>
      <origin
        xyz="0 0.006 0"
        rpy="0 0 0" />
      <geometry>
        <mesh
          filename="arm_description/meshes/gripper_convex.STL" />
      </geometry>
    </collision>
  </link>
  <joint
    name="Joint_gripper_r"
    type="prismatic">
    <origin
      xyz="0.081 0 -0.02045"
      rpy="0 0 0" />
    <parent
      link="Link_3" />
    <child
      link="Link_gripper_r" />
    <axis
      xyz="0 1 0" />
    <limit
      lower="0"
      upper="0.042"
      effort="0"
      velocity="0" />
  </joint>
  <link
    name="Link_gripper_l">
    <!--<inertial>
      <origin
        xyz="-7.8597E-08 -0.00028755 0.011814"
        rpy="0 0 0" />
      <mass
        value="0.1234" />
      <inertia
        ixx="9.6329E-05"
        ixy="-1.9852E-19"
        ixz="-3.9588E-19"
        iyy="9.4959E-05"
        iyz="1.3325E-09"
        izz="0.00017146" />
    </inertial>-->
    <visual>
      <origin
        xyz="0 -0.006 0"
        rpy="3.14159265 0 0" />
      <geometry>
        <mesh
          filename="arm_description/meshes/gripper_convex.STL" />
      </geometry>
      <material
        name="">
        <color
          rgba="0.75294 0.75294 0.75294 1" />
      </material>
    </visual>
    <collision>
      <origin
        xyz="0 -0.006 0"
        rpy="3.14159265 0 0" />
      <geometry>
        <mesh
          filename="arm_description/meshes/gripper_convex.STL" />
      </geometry>
    </collision>
  </link>
  <joint
    name="Joint_gripper_l"
    type="prismatic">
    <origin
      xyz="0.081 0 -0.02045"
      rpy="0 0 0" />
    <parent
      link="Link_3" />
    <child
      link="Link_gripper_l" />
    <axis
      xyz="0 -1 0" />
    <limit
      lower="0"
      upper="0.042"
      effort="0"
      velocity="0" />
  </joint>
  <link
    name="Link_tcp">
  </link>
  <joint
    name="Joint_tcp"
    type="fixed">
    <origin
      xyz="0.14565 0 -0.02045"
      rpy="0 0 0" />
    <parent
      link="Link_3" />
    <child
      link="Link_tcp" />
  </joint>
</robot>
